from datetime import date, time

import pytest
from django.core.exceptions import ValidationError
from faker import Faker

from journal.models import AppointmentEntry

fake = Faker()


@pytest.mark.django_db
def test_create_appointment_entry(custom_user):
    """
    GIVEN an appointment entry model
    WHEN creating an appointment entry
    THEN user should have successfully created an appointment entry
    """
    appointment_entry = AppointmentEntry.objects.create(
        user=custom_user,
        title="Dentist",
        date="2023-07-06",
        time_from=time(10, 0),
        time_until=time(11, 0),
    )
    appointment_entry.save()
    appointment_entries = AppointmentEntry.objects.all()
    assert len(appointment_entries) == 1
    assert appointment_entries[0].user == custom_user
    assert appointment_entries[0].title == "Dentist"
    assert appointment_entries[0].date == date(2023, 7, 6)
    assert (
        isinstance(appointment_entries[0].date, date)
        and appointment_entries[0].date is not None
    )
    assert appointment_entries[0].time_from == time(10, 0)
    assert (
        isinstance(appointment_entries[0].time_from, time)
        and appointment_entries[0].time_from is not None
    )
    assert appointment_entries[0].time_until == time(11, 0)
    assert (
        isinstance(appointment_entries[0].time_until, time)
        and appointment_entries[0].time_until is not None
    )


@pytest.mark.django_db
def test_create_appointment_entry_from_until(custom_user):
    """
    GIVEN an appointment entry model
    WHEN creating an appointment entry
    THEN a ValidationError is raised
    """
    with pytest.raises(ValidationError):
        appointment_entry = AppointmentEntry.objects.create(
            user=custom_user,
            title="Dentist",
            date="2023-07-06",
            time_from=time(10, 0),
            time_until=time(9, 0),
        )
        appointment_entry.clean()
